<?xml version="1.0"?>
<robot xmlns:xacro="http://www.ros.org/wiki/xacro">
   <xacro:include filename="$(find agent_description)/urdf/common_inertia.xacro" />
    <xacro:macro name="wheel_xacro" params="wheel_name xyz">
        <link name="${wheel_name}_wheel_link">
            <visual>
                <origin xyz="0 0 0" rpy="1.57079 0 0" />
                <geometry>
                    <cylinder length="0.04" radius="0.032" />
                </geometry>
                <material name="yellow">
                    <color rgba="1.0 1.0 0.0 0.8"/>
                </material>
            </visual>
            <collision>
                <origin xyz="0 0 0" rpy="1.57079 0 0" />
                <geometry>
                    <cylinder length="0.04" radius="0.032" />
                </geometry>
                <material name="yellow">
                    <color rgba="1.0 1.0 0.0 0.8"/>
                </material>
            </collision>
            <xacro:cylinder_inertia m="0.1" h="0.04" r="0.032"/>
        </link>
        <!-- ros2_control 只负责控制接口，物理仿真稳定性还需要在 <gazebo> 标签中为每个关节添加 ODE 参数： -->
        <gazebo reference="${wheel_name}_wheel_link">
            <mu1 value="20.0" />
            <mu2 value="20.0" />
            <kp value="1000000000.0" />
            <kd value="1.0" />
        </gazebo>
        <gazebo reference="${wheel_name}_wheel_link">
            <material>Gazebo/Yellow</material>
        </gazebo>

        <joint name="${wheel_name}_wheel_joint" type="continuous">
            <parent link="base_link" />
            <child link="${wheel_name}_wheel_link" />
            <origin xyz="${xyz}" />
            <axis xyz="0 1 0" />
        </joint>
    </xacro:macro>
</robot>
